Workbook

Sheet Summary
A1: A2Z DSA — progress
A2: 456 problems · 18 steps · sources cross-checked, see reference/CROSS_CHECK.md
A4: Solved | B4: =COUNTIF(Tracker!$I$2:$I$457,"Done")
A5: Remaining | B5: =B6-B4
A6: Total | B6: =COUNTA(Tracker!$F$2:$F$457)
A7: Complete | B7: =IFERROR(B4/B6,0)
A9: By difficulty
A10: Difficulty | B10: Total | C10: Solved | D10: Complete
A11: Easy | B11: =COUNTIF(Tracker!$G$2:$G$457,A11) | C11: =COUNTIFS(Tracker!$G$2:$G$457,A11,Tracker!$I$2:$I$457,"Done") | D11: =IFERROR(C11/B11,0)
A12: Medium | B12: =COUNTIF(Tracker!$G$2:$G$457,A12) | C12: =COUNTIFS(Tracker!$G$2:$G$457,A12,Tracker!$I$2:$I$457,"Done") | D12: =IFERROR(C12/B12,0)
A13: Hard | B13: =COUNTIF(Tracker!$G$2:$G$457,A13) | C13: =COUNTIFS(Tracker!$G$2:$G$457,A13,Tracker!$I$2:$I$457,"Done") | D13: =IFERROR(C13/B13,0)
A15: By step
A16: Step | B16: Title | C16: Total | D16: Solved | E16: Left | F16: Complete
A17: 1 | B17: Step 1: Learn the basics | C17: =COUNTIF(Tracker!$B$2:$B$457,$A17) | D17: =COUNTIFS(Tracker!$B$2:$B$457,$A17,Tracker!$I$2:$I$457,"Done") | E17: =C17-D17 | F17: =IFERROR(D17/C17,0)
A18: 2 | B18: Step 2: Learn Important Sorting Techniques | C18: =COUNTIF(Tracker!$B$2:$B$457,$A18) | D18: =COUNTIFS(Tracker!$B$2:$B$457,$A18,Tracker!$I$2:$I$457,"Done") | E18: =C18-D18 | F18: =IFERROR(D18/C18,0)
A19: 3 | B19: Step 3: Solve Problems on Arrays [Easy -> Medium -> Hard] | C19: =COUNTIF(Tracker!$B$2:$B$457,$A19) | D19: =COUNTIFS(Tracker!$B$2:$B$457,$A19,Tracker!$I$2:$I$457,"Done") | E19: =C19-D19 | F19: =IFERROR(D19/C19,0)
A20: 4 | B20: Step 4: Binary Search [1D, 2D Arrays, Search Space] | C20: =COUNTIF(Tracker!$B$2:$B$457,$A20) | D20: =COUNTIFS(Tracker!$B$2:$B$457,$A20,Tracker!$I$2:$I$457,"Done") | E20: =C20-D20 | F20: =IFERROR(D20/C20,0)
A21: 5 | B21: Step 5: Strings [Basic and Medium] | C21: =COUNTIF(Tracker!$B$2:$B$457,$A21) | D21: =COUNTIFS(Tracker!$B$2:$B$457,$A21,Tracker!$I$2:$I$457,"Done") | E21: =C21-D21 | F21: =IFERROR(D21/C21,0)
A22: 6 | B22: Step 6: Learn LinkedList [Single LL, Double LL, Medium, Hard Problems] | C22: =COUNTIF(Tracker!$B$2:$B$457,$A22) | D22: =COUNTIFS(Tracker!$B$2:$B$457,$A22,Tracker!$I$2:$I$457,"Done") | E22: =C22-D22 | F22: =IFERROR(D22/C22,0)
A23: 7 | B23: Step 7: Recursion [PatternWise] | C23: =COUNTIF(Tracker!$B$2:$B$457,$A23) | D23: =COUNTIFS(Tracker!$B$2:$B$457,$A23,Tracker!$I$2:$I$457,"Done") | E23: =C23-D23 | F23: =IFERROR(D23/C23,0)
A24: 8 | B24: Step 8: Bit Manipulation [Concepts & Problems] | C24: =COUNTIF(Tracker!$B$2:$B$457,$A24) | D24: =COUNTIFS(Tracker!$B$2:$B$457,$A24,Tracker!$I$2:$I$457,"Done") | E24: =C24-D24 | F24: =IFERROR(D24/C24,0)
A25: 9 | B25: Step 9: Stack and Queues [Learning, Pre-In-Post-fix, Monotonic Stack, Implementation] | C25: =COUNTIF(Tracker!$B$2:$B$457,$A25) | D25: =COUNTIFS(Tracker!$B$2:$B$457,$A25,Tracker!$I$2:$I$457,"Done") | E25: =C25-D25 | F25: =IFERROR(D25/C25,0)
A26: 10 | B26: Step 10: Sliding Window & Two Pointer Combined Problems | C26: =COUNTIF(Tracker!$B$2:$B$457,$A26) | D26: =COUNTIFS(Tracker!$B$2:$B$457,$A26,Tracker!$I$2:$I$457,"Done") | E26: =C26-D26 | F26: =IFERROR(D26/C26,0)
A27: 11 | B27: Step 11: Heaps [Learning, Medium, Hard Problems] | C27: =COUNTIF(Tracker!$B$2:$B$457,$A27) | D27: =COUNTIFS(Tracker!$B$2:$B$457,$A27,Tracker!$I$2:$I$457,"Done") | E27: =C27-D27 | F27: =IFERROR(D27/C27,0)
A28: 12 | B28: Step 12: Greedy Algorithms [Easy, Medium/Hard] | C28: =COUNTIF(Tracker!$B$2:$B$457,$A28) | D28: =COUNTIFS(Tracker!$B$2:$B$457,$A28,Tracker!$I$2:$I$457,"Done") | E28: =C28-D28 | F28: =IFERROR(D28/C28,0)
... A34: 18 | B34: Step 18: Strings | C34: =COUNTIF(Tracker!$B$2:$B$457,$A34) | D34: =COUNTIFS(Tracker!$B$2:$B$457,$A34,Tracker!$I$2:$I$457,"Done") | E34: =C34-D34 | F34: =IFERROR(D34/C34,0)
B35: All steps | C35: =SUM(C17:C34) | D35: =SUM(D17:D34) | E35: =SUM(E17:E34) | F35: =IFERROR(D35/C35,0)
A37: How to use
A38: Cream cells on Tracker | B38: The only cells you edit: Status, Date solved, Revisions, Confidence, Time, Notes.
A39: Status | B39: Pick from the dropdown: Not started · In progress · Done · Revisit.
A40: Example row | B40: Done · 2026-09-21 · 2 revisions · High · 25 min · "two-pointer, missed the dup case".
A41: Links | B41: LC/GFG/CN/YT/BLOG/TUF open the problem. Sol p. is the solutions-PDF page. Purple = no LeetCode version. LC? = suggested by another source.
A42: This sheet | B42: All figures are live COUNTIFS over Tracker — nothing here needs editing.

Sheet Tracker
A1: # | B1: Step | C1: Step title | D1: Sub-step | E1: Sub-step title | F1: Problem | G1: Difficulty | H1: Topic | I1: Status | J1: Date solved | K1: Revisions | L1: Confidence | M1: Time (min) | N1: Notes | O1: LC | P1: GFG | Q1: CN | R1: YT | S1: BLOG | T1: TUF | U1: Alt link | V1: LC (suggested) | W1: Sol p. | X1: ID (do not edit)
A2: 1 | B2: 1 | C2: Step 1: Learn the basics | D2: 1 | E2: 1. Things to Know in C++/Java/Python or any language | F2: User Input / Output | G2: Easy | H2: Introduction to DSA | I2: Not started | P2: GFG | Q2: CN | R2: YT | S2: BLOG | T2: TUF | X2: s1-user-input-output
A3: 2 | B3: 1 | C3: Step 1: Learn the basics | D3: 1 | E3: 1. Things to Know in C++/Java/Python or any language | F3: Data Types | G3: Easy | H3: Introduction to DSA | I3: Not started | P3: GFG | Q3: CN | R3: YT | T3: TUF | X3: s1-data-types
A4: 3 | B4: 1 | C4: Step 1: Learn the basics | D4: 1 | E4: 1. Things to Know in C++/Java/Python or any language | F4: If Else statements | G4: Easy | H4: Introduction to DSA | I4: Not started | P4: GFG | Q4: CN | R4: YT | S4: BLOG | T4: TUF | X4: s1-if-else-statements
A5: 4 | B5: 1 | C5: Step 1: Learn the basics | D5: 1 | E5: 1. Things to Know in C++/Java/Python or any language | F5: Switch Statement | G5: Easy | H5: Introduction to DSA | I5: Not started | P5: GFG | Q5: CN | R5: YT | S5: BLOG | T5: TUF | X5: s1-switch-statement
A6: 5 | B6: 1 | C6: Step 1: Learn the basics | D6: 1 | E6: 1. Things to Know in C++/Java/Python or any language | F6: What are arrays, strings? | G6: Easy | H6: Introduction to DSA | I6: Not started | R6: YT | T6: TUF | X6: s1-what-are-arrays-strings
A7: 6 | B7: 1 | C7: Step 1: Learn the basics | D7: 1 | E7: 1. Things to Know in C++/Java/Python or any language | F7: For loops | G7: Easy | H7: Introduction to DSA | I7: Not started | Q7: CN | R7: YT | S7: BLOG | T7: TUF | X7: s1-for-loops
A8: 7 | B8: 1 | C8: Step 1: Learn the basics | D8: 1 | E8: 1. Things to Know in C++/Java/Python or any language | F8: While loops | G8: Easy | H8: Introduction to DSA | I8: Not started | P8: GFG | Q8: CN | R8: YT | S8: BLOG | T8: TUF | X8: s1-while-loops
A9: 8 | B9: 1 | C9: Step 1: Learn the basics | D9: 1 | E9: 1. Things to Know in C++/Java/Python or any language | F9: Functions (Pass by Reference and Value) | G9: Easy | H9: Introduction to DSA | I9: Not started | P9: GFG | Q9: CN | R9: YT | T9: TUF | X9: s1-functions-pass-by-reference-and-value
A10: 9 | B10: 1 | C10: Step 1: Learn the basics | D10: 1 | E10: 1. Things to Know in C++/Java/Python or any language | F10: Time Complexity [Learn Basics, and then analyse in next Steps] | G10: Easy | H10: Introduction to DSA | I10: Not started | R10: YT | S10: BLOG | X10: s1-time-complexity-learn-basics-and-then-analyse-in
A11: 10 | B11: 1 | C11: Step 1: Learn the basics | D11: 2 | E11: 2. Build-up Logical Thinking | F11: Patterns | G11: Easy | H11: Maths, Data Structures | I11: Not started | R11: YT | S11: BLOG | T11: TUF | X11: s1-patterns
A12: 11 | B12: 1 | C12: Step 1: Learn the basics | D12: 3 | E12: 3. Learn STL/Java-Collections or similar thing in your language | F12: C++ STL | G12: Medium | H12: C++, Introduction to DSA | I12: Not started | P12: GFG | R12: YT | S12: BLOG | X12: s1-c-stl
A13: 12 | B13: 1 | C13: Step 1: Learn the basics | D13: 3 | E13: 3. Learn STL/Java-Collections or similar thing in your language | F13: Java Collections | G13: Easy | H13: Java, Introduction to DSA | I13: Not started | X13: s1-java-collections
A14: 13 | B14: 1 | C14: Step 1: Learn the basics | D14: 4 | E14: 4. Know Basic Maths | F14: Count Digits | G14: Easy | H14: Maths, Data Structures | I14: Not started | P14: GFG | Q14: CN | R14: YT | S14: BLOG | T14: TUF | W14: 2 | X14: s1-count-digits
A15: 14 | B15: 1 | C15: Step 1: Learn the basics | D15: 4 | E15: 4. Know Basic Maths | F15: Reverse a Number | G15: Easy | H15: Maths, Data Structures | I15: Not started | O15: LC | P15: GFG | Q15: CN | R15: YT | S15: BLOG | T15: TUF | W15: 3 | X15: s1-reverse-a-number
A16: 15 | B16: 1 | C16: Step 1: Learn the basics | D16: 4 | E16: 4. Know Basic Maths | F16: Check Palindrome | G16: Easy | H16: Maths, Data Structures | I16: Not started | O16: LC | P16: GFG | Q16: CN | R16: YT | S16: BLOG | T16: TUF | W16: 5 | X16: s1-check-palindrome
A17: 16 | B17: 1 | C17: Step 1: Learn the basics | D17: 4 | E17: 4. Know Basic Maths | F17: GCD Or HCF | G17: Easy | H17: Maths, Data Structures | I17: Not started | P17: GFG | Q17: CN | R17: YT | S17: BLOG | T17: TUF | W17: 6 | X17: s1-gcd-or-hcf
A18: 17 | B18: 1 | C18: Step 1: Learn the basics | D18: 4 | E18: 4. Know Basic Maths | F18: Armstrong Numbers | G18: Easy | H18: Maths, Data Structures | I18: Not started | O18: LC | P18: GFG | Q18: CN | R18: YT | S18: BLOG | T18: TUF | W18: 8 | X18: s1-armstrong-numbers
A19: 18 | B19: 1 | C19: Step 1: Learn the basics | D19: 4 | E19: 4. Know Basic Maths | F19: Print all Divisors | G19: Easy | H19: Maths, Data Structures | I19: Not started | P19: GFG | Q19: CN | R19: YT | S19: BLOG | T19: TUF | W19: 9 | X19: s1-print-all-divisors
A20: 19 | B20: 1 | C20: Step 1: Learn the basics | D20: 4 | E20: 4. Know Basic Maths | F20: Check for Prime | G20: Easy | H20: Maths, Data Structures | I20: Not started | P20: GFG | Q20: CN | R20: YT | S20: BLOG | T20: TUF | W20: 11 | X20: s1-check-for-prime
A21: 20 | B21: 1 | C21: Step 1: Learn the basics | D21: 5 | E21: 5. Learn Basic Recursion | F21: Understand recursion by print something N times | G21: Easy | H21: Recursion, Data Structures | I21: Not started | P21: GFG | Q21: CN | R21: YT | S21: BLOG | W21: 12 | X21: s1-understand-recursion-by-print-something-n-times
A22: 21 | B22: 1 | C22: Step 1: Learn the basics | D22: 5 | E22: 5. Learn Basic Recursion | F22: Print name N times using recursion | G22: Easy | H22: Recursion, Data Structures | I22: Not started | P22: GFG | Q22: CN | R22: YT | S22: BLOG | W22: 13 | X22: s1-print-name-n-times-using-recursion
A23: 22 | B23: 1 | C23: Step 1: Learn the basics | D23: 5 | E23: 5. Learn Basic Recursion | F23: Print 1 to N using recursion | G23: Easy | H23: Recursion, Data Structures | I23: Not started | P23: GFG | Q23: CN | R23: YT | S23: BLOG | W23: 14 | X23: s1-print-1-to-n-using-recursion
A24: 23 | B24: 1 | C24: Step 1: Learn the basics | D24: 5 | E24: 5. Learn Basic Recursion | F24: Print N to 1 using recursion | G24: Easy | H24: Recursion, Data Structures | I24: Not started | P24: GFG | Q24: CN | R24: YT | S24: BLOG | W24: 15 | X24: s1-print-n-to-1-using-recursion
A25: 24 | B25: 1 | C25: Step 1: Learn the basics | D25: 5 | E25: 5. Learn Basic Recursion | F25: Sum of first N numbers | G25: Easy | H25: Maths, Data Structures | I25: Not started | P25: GFG | Q25: CN | R25: YT | S25: BLOG | T25: TUF | W25: 16 | X25: s1-sum-of-first-n-numbers
A26: 25 | B26: 1 | C26: Step 1: Learn the basics | D26: 5 | E26: 5. Learn Basic Recursion | F26: Factorial of N numbers | G26: Easy | H26: Maths, Data Structures | I26: Not started | P26: GFG | Q26: CN | R26: YT | S26: BLOG | T26: TUF | W26: 17 | X26: s1-factorial-of-n-numbers
A27: 26 | B27: 1 | C27: Step 1: Learn the basics | D27: 5 | E27: 5. Learn Basic Recursion | F27: Reverse an array | G27: Easy | H27: Arrays, Data Structures | I27: Not started | P27: GFG | Q27: CN | R27: YT | S27: BLOG | T27: TUF | V27: LC? | W27: 17 | X27: s1-reverse-an-array
A28: 27 | B28: 1 | C28: Step 1: Learn the basics | D28: 5 | E28: 5. Learn Basic Recursion | F28: Check if a string is palindrome or not | G28: Medium | H28: String, Data Structures | I28: Not started | O28: LC | P28: GFG | Q28: CN | R28: YT | S28: BLOG | T28: TUF | W28: 18 | X28: s1-check-if-a-string-is-palindrome-or-not
A29: 28 | B29: 1 | C29: Step 1: Learn the basics | D29: 5 | E29: 5. Learn Basic Recursion | F29: Fibonacci Number | G29: Easy | H29: Maths, Data Structures | I29: Not started | O29: LC | P29: GFG | Q29: CN | R29: YT | S29: BLOG | T29: TUF | W29: 19 | X29: s1-fibonacci-number
A30: 29 | B30: 1 | C30: Step 1: Learn the basics | D30: 6 | E30: 6. Learn Basic Hashing | F30: Hashing Theory | G30: Medium | H30: Hashing, Data Structures | I30: Not started | R30: YT | S30: BLOG | W30: 20 | X30: s1-hashing-theory
A31: 30 | B31: 1 | C31: Step 1: Learn the basics | D31: 6 | E31: 6. Learn Basic Hashing | F31: Counting frequencies of array elements | G31: Easy | H31: Arrays, Hashing, Sorting, Data Structures | I31: Not started | P31: GFG | Q31: CN | S31: BLOG | W31: 21 | X31: s1-counting-frequencies-of-array-elements
A32: 31 | B32: 1 | C32: Step 1: Learn the basics | D32: 6 | E32: 6. Learn Basic Hashing | F32: Find the highest/lowest frequency element | G32: Easy | H32: Arrays, Hashing, Data Structures | I32: Not started | O32: LC | P32: GFG | Q32: CN | S32: BLOG | T32: TUF | W32: 23 | X32: s1-find-the-highest-lowest-frequency-element
A33: 32 | B33: 2 | C33: Step 2: Learn Important Sorting Techniques | D33: 1 | E33: 1. Sorting-I | F33: Selection Sort | G33: Easy | H33: Sorting, Arrays, Data Structures | I33: Not started | P33: GFG | Q33: CN | R33: YT | S33: BLOG | T33: TUF | W33: 25 | X33: s2-selection-sort
A34: 33 | B34: 2 | C34: Step 2: Learn Important Sorting Techniques | D34: 1 | E34: 1. Sorting-I | F34: Bubble Sort | G34: Easy | H34: Sorting, Arrays, Data Structures | I34: Not started | P34: GFG | Q34: CN | R34: YT | S34: BLOG | T34: TUF | W34: 26 | X34: s2-bubble-sort
A35: 34 | B35: 2 | C35: Step 2: Learn Important Sorting Techniques | D35: 1 | E35: 1. Sorting-I | F35: Insertion Sort | G35: Easy | H35: Sorting, Data Structures | I35: Not started | P35: GFG | Q35: CN | R35: YT | S35: BLOG | T35: TUF | W35: 27 | X35: s2-insertion-sort
A36: 35 | B36: 2 | C36: Step 2: Learn Important Sorting Techniques | D36: 2 | E36: 2. Sorting-II | F36: Merge Sort | G36: Medium | H36: Arrays, Sorting, Data Structures | I36: Not started | P36: GFG | Q36: CN | R36: YT | S36: BLOG | T36: TUF | W36: 29 | X36: s2-merge-sort
A37: 36 | B37: 2 | C37: Step 2: Learn Important Sorting Techniques | D37: 2 | E37: 2. Sorting-II | F37: Recursive Bubble Sort | G37: Easy | H37: Sorting, Data Structures | I37: Not started | P37: GFG | Q37: CN | S37: BLOG | W37: 31 | X37: s2-recursive-bubble-sort
A38: 37 | B38: 2 | C38: Step 2: Learn Important Sorting Techniques | D38: 2 | E38: 2. Sorting-II | F38: Recursive Insertion Sort | G38: Easy | H38: Recursion, Sorting, Data Structures | I38: Not started | P38: GFG | Q38: CN | S38: BLOG | W38: 32 | X38: s2-recursive-insertion-sort
A39: 38 | B39: 2 | C39: Step 2: Learn Important Sorting Techniques | D39: 2 | E39: 2. Sorting-II | F39: Quick Sort | G39: Easy | H39: Arrays, Sorting, Data Structures | I39: Not started | P39: GFG | Q39: CN | R39: YT | S39: BLOG | T39: TUF | W39: 34 | X39: s2-quick-sort
A40: 39 | B40: 3 | C40: Step 3: Solve Problems on Arrays [Easy -> Medium -> Hard] | D40: 1 | E40: 1. Easy | F40: Largest Element in an Array | G40: Easy | H40: Arrays, Data Structures | I40: Not started | P40: GFG | Q40: CN | R40: YT | S40: BLOG | T40: TUF | W40: 38 | X40: s3-largest-element-in-an-array
...
